
namespace ExceptionHandling1
{
    internal class Program
    {
        static void Main0()
        {
            Class1 obj = new Class1();
            obj = null;
            int x = Convert.ToInt32(Console.ReadLine());
            obj.P1 = 100 / x;
            Console.WriteLine(obj.P1);
            Console.ReadLine();
        }
        static void Main1() //simple try block with catch
        {
            Class1 obj = new Class1();
            try
            {
                //
                //obj = null;
                int x = Convert.ToInt32(Console.ReadLine());
                obj.P1 = 100 / x;
                Console.WriteLine(obj.P1);
                Console.WriteLine("No Exceptions");
            }
            catch
            {
                Console.WriteLine("Exception occurred");
            }

        }
        static void Main2()//try with multiple catch blocks
        {
            Class1 obj = new Class1();
            try
            {
                obj = null;
                int x = Convert.ToInt32(Console.ReadLine());
                obj.P1 = 100 / x;
                Console.WriteLine(obj.P1);
                Console.WriteLine("No Exceptions");
            }
            catch (DivideByZeroException)
            {
                Console.WriteLine("DBException occurred");
            }
            catch (NullReferenceException ex)
            {
                Console.WriteLine("NRException occurred");
            }
            catch (FormatException ex)
            {
                Console.WriteLine("FormatException occurred");
            }
            Console.ReadLine();
        }
        static void Main3()// catching base class exceptions
        {
            Class1 obj = new Class1();
            try
            {
                obj = null;
                int x = Convert.ToInt32(Console.ReadLine());
                obj.P1 = 100 / x;
                Console.WriteLine(obj.P1);
                Console.WriteLine("No Exceptions");
            }

            //catch (SystemException ex)
            catch (FormatException ex)
            {
                Console.WriteLine("FormatException occurred");
            }
            catch (NullReferenceException ex)
            {
                Console.WriteLine("NRException occurred");
            }
            catch (DivideByZeroException ex)
            //catch (ArithmeticException ex) 
            //catch (SystemException ex) //base class exception has to caught after derived class exceptions
            {
                Console.WriteLine("DBException occurred");
            }
            catch (Exception ex) //catches all unhandled exceptions
            {
                Console.WriteLine(ex.Message);
            }
            Console.ReadLine();
        }

        static void Main4()// finally block
        {
            Class1 obj = new Class1();
            try
            {
                //obj = null;
                int x = Convert.ToInt32(Console.ReadLine());
                obj.P1 = 100 / x;
                Console.WriteLine(obj.P1);
                Console.WriteLine("No Exceptions");
            }
            catch (FormatException ex)
            {
                Console.WriteLine("FormatException occurred");
            }
            catch (NullReferenceException ex)
            {
                Console.WriteLine("NRException occurred");
            }
            //catch (DivideByZeroException ex) 
            //catch (ArithmeticException ex) 
            catch (SystemException ex) //base class exception has to caught after derived class exceptions
            {
                Console.WriteLine("DBException occurred");
            }
            catch (Exception ex) //catches all unhandled exceptions
            {
                Console.WriteLine(ex.Message);
            }
            //finally runs when Exception does not occur, 
            //or Exception occurs and is handled or 
            //Exception occurs and is NOT handled 
            finally
            {
                Console.WriteLine("finally");

            }
            Console.WriteLine("after finally");
        }
        static void Main5()// nested try block
        {
            Class1 obj = new Class1();
            try
            {
                //obj = null;
                int x = Convert.ToInt32(Console.ReadLine());
                obj.P1 = 100 / x;
                Console.WriteLine(obj.P1);
                Console.WriteLine("No Exceptions");
            }

            catch (FormatException ex)
            {
                try
                {
                    Console.WriteLine("FormatException occurred. Enter only numbers");
                    int x = Convert.ToInt32(Console.ReadLine());
                    obj.P1 = 100 / x;
                    Console.WriteLine(obj.P1);
                }
                catch
                {
                    Console.WriteLine("nested try catch example");
                }
                finally
                {
                    Console.WriteLine("nested try finally example");
                }
            }
            catch (NullReferenceException ex)
            {
                Console.WriteLine("NRException occurred");
            }
            catch (DivideByZeroException ex)
            {
                Console.WriteLine("DBException occurred");
            }
            catch (Exception ex) //catches all unhandled exceptions
            {
                Console.WriteLine(ex.Message);
            }
            finally
            {
                Console.WriteLine("finally");

            }
            Console.ReadLine();
        }
    }

    public class Class1
    {
        private int p1;
        public int P1
        {
            get { return p1; }
            set
            {
                p1 = value;
            }
        }
    }
}

namespace ExceptionHandling2
{
    class Program
    {
        static void Main()
        {
            Class1 obj = new Class1();
            try
            {
                int x = Convert.ToInt32(Console.ReadLine());
                obj.P1 = x;
                Console.WriteLine(obj.P1);
                Console.WriteLine("No Exceptions");
            }
            catch (FormatException ex)
            {
                Console.WriteLine("FormatException occurred");
            }
            catch (NullReferenceException ex)
            {
                Console.WriteLine("NRException occurred");
            }
            catch (InvalidP1Exception ex)
            {
                Console.WriteLine(ex.Message);
            }
            catch (ApplicationException ex) //all user defined exceptions that have not been handled before
            {
                Console.WriteLine(ex.Message);
            }
            catch (SystemException ex) //all .net exceptions that have not been handled before
            {
                Console.WriteLine(ex.Message);
            }
            catch (Exception ex)
            {
                Console.WriteLine(ex.Message);
            }


            Console.ReadLine();
        }
    }
    public class InvalidP1Exception :ApplicationException
    {
        public InvalidP1Exception(string message)// : base(message)
        {
          
        }

    }
    public class Class1
    {
        private int p1;
        public int P1
        {
            get
            {
                return p1;
            }
            set
            {
                if (value < 100)
                    p1 = value;
                else
                {
                    //Exception ex = new Exception();
                    //throw ex;

                    //throw new Exception();
                    //throw new Exception("Invalid P1");
                    //throw new InvalidP1Exception();
                    throw new InvalidP1Exception("Invalid P1");

                }
            }
        }
    }

   
}

